[2022-12-15 14:54:24,262] {processor.py:153} INFO - Started process (PID=11031) to work on /opt/airflow/dags/test_dag.py
[2022-12-15 14:54:24,263] {processor.py:641} INFO - Processing file /opt/airflow/dags/test_dag.py for tasks to queue
[2022-12-15 14:54:24,264] {logging_mixin.py:115} INFO - [2022-12-15 14:54:24,264] {dagbag.py:508} INFO - Filling up the DagBag from /opt/airflow/dags/test_dag.py
[2022-12-15 14:54:24,501] {processor.py:651} INFO - DAG(s) dict_keys(['test_dag']) retrieved from /opt/airflow/dags/test_dag.py
[2022-12-15 14:54:24,556] {logging_mixin.py:115} INFO - [2022-12-15 14:54:24,555] {dag.py:2420} INFO - Sync 1 DAGs
[2022-12-15 14:54:24,627] {logging_mixin.py:115} INFO - [2022-12-15 14:54:24,626] {dag.py:2972} INFO - Setting next_dagrun for test_dag to 2022-12-14T00:00:00+00:00, run_after=2022-12-15T00:00:00+00:00
[2022-12-15 14:54:24,655] {processor.py:161} INFO - Processing /opt/airflow/dags/test_dag.py took 0.401 seconds
[2022-12-15 14:54:55,030] {processor.py:153} INFO - Started process (PID=11085) to work on /opt/airflow/dags/test_dag.py
[2022-12-15 14:54:55,030] {processor.py:641} INFO - Processing file /opt/airflow/dags/test_dag.py for tasks to queue
[2022-12-15 14:54:55,031] {logging_mixin.py:115} INFO - [2022-12-15 14:54:55,031] {dagbag.py:508} INFO - Filling up the DagBag from /opt/airflow/dags/test_dag.py
[2022-12-15 14:54:55,236] {processor.py:651} INFO - DAG(s) dict_keys(['test_dag']) retrieved from /opt/airflow/dags/test_dag.py
[2022-12-15 14:54:55,302] {logging_mixin.py:115} INFO - [2022-12-15 14:54:55,302] {dag.py:2420} INFO - Sync 1 DAGs
[2022-12-15 14:54:55,374] {logging_mixin.py:115} INFO - [2022-12-15 14:54:55,373] {dag.py:2972} INFO - Setting next_dagrun for test_dag to 2022-12-14T00:00:00+00:00, run_after=2022-12-15T00:00:00+00:00
[2022-12-15 14:54:55,408] {processor.py:161} INFO - Processing /opt/airflow/dags/test_dag.py took 0.384 seconds
[2022-12-15 17:45:20,798] {processor.py:153} INFO - Started process (PID=11129) to work on /opt/airflow/dags/test_dag.py
[2022-12-15 17:45:20,808] {processor.py:641} INFO - Processing file /opt/airflow/dags/test_dag.py for tasks to queue
[2022-12-15 17:45:20,810] {logging_mixin.py:115} INFO - [2022-12-15 17:45:20,810] {dagbag.py:508} INFO - Filling up the DagBag from /opt/airflow/dags/test_dag.py
[2022-12-15 17:45:21,256] {processor.py:651} INFO - DAG(s) dict_keys(['test_dag']) retrieved from /opt/airflow/dags/test_dag.py
[2022-12-15 17:45:21,331] {logging_mixin.py:115} INFO - [2022-12-15 17:45:21,331] {dag.py:2420} INFO - Sync 1 DAGs
[2022-12-15 17:45:21,443] {logging_mixin.py:115} INFO - [2022-12-15 17:45:21,443] {dag.py:2972} INFO - Setting next_dagrun for test_dag to 2022-12-14T00:00:00+00:00, run_after=2022-12-15T00:00:00+00:00
[2022-12-15 17:45:21,500] {processor.py:161} INFO - Processing /opt/airflow/dags/test_dag.py took 0.713 seconds
[2022-12-15 17:45:51,628] {processor.py:153} INFO - Started process (PID=11192) to work on /opt/airflow/dags/test_dag.py
[2022-12-15 17:45:51,629] {processor.py:641} INFO - Processing file /opt/airflow/dags/test_dag.py for tasks to queue
[2022-12-15 17:45:51,629] {logging_mixin.py:115} INFO - [2022-12-15 17:45:51,629] {dagbag.py:508} INFO - Filling up the DagBag from /opt/airflow/dags/test_dag.py
[2022-12-15 17:45:51,737] {processor.py:651} INFO - DAG(s) dict_keys(['test_dag']) retrieved from /opt/airflow/dags/test_dag.py
[2022-12-15 17:45:51,761] {logging_mixin.py:115} INFO - [2022-12-15 17:45:51,761] {dag.py:2420} INFO - Sync 1 DAGs
[2022-12-15 17:45:51,789] {logging_mixin.py:115} INFO - [2022-12-15 17:45:51,788] {dag.py:2972} INFO - Setting next_dagrun for test_dag to 2022-12-14T00:00:00+00:00, run_after=2022-12-15T00:00:00+00:00
[2022-12-15 17:45:51,801] {processor.py:161} INFO - Processing /opt/airflow/dags/test_dag.py took 0.176 seconds
[2022-12-15 17:46:22,684] {processor.py:153} INFO - Started process (PID=11246) to work on /opt/airflow/dags/test_dag.py
[2022-12-15 17:46:22,722] {processor.py:641} INFO - Processing file /opt/airflow/dags/test_dag.py for tasks to queue
[2022-12-15 17:46:22,723] {logging_mixin.py:115} INFO - [2022-12-15 17:46:22,723] {dagbag.py:508} INFO - Filling up the DagBag from /opt/airflow/dags/test_dag.py
[2022-12-15 17:46:23,059] {processor.py:651} INFO - DAG(s) dict_keys(['test_dag']) retrieved from /opt/airflow/dags/test_dag.py
[2022-12-15 17:46:23,161] {processor.py:164} ERROR - Got an exception! Propagating...
Traceback (most recent call last):
  File "/home/airflow/.local/lib/python3.7/site-packages/sqlalchemy/engine/base.py", line 3243, in _wrap_pool_connect
    return fn()
  File "/home/airflow/.local/lib/python3.7/site-packages/sqlalchemy/pool/base.py", line 310, in connect
    return _ConnectionFairy._checkout(self)
  File "/home/airflow/.local/lib/python3.7/site-packages/sqlalchemy/pool/base.py", line 868, in _checkout
    fairy = _ConnectionRecord.checkout(pool)
  File "/home/airflow/.local/lib/python3.7/site-packages/sqlalchemy/pool/base.py", line 476, in checkout
    rec = pool._do_get()
  File "/home/airflow/.local/lib/python3.7/site-packages/sqlalchemy/pool/impl.py", line 146, in _do_get
    self._dec_overflow()
  File "/home/airflow/.local/lib/python3.7/site-packages/sqlalchemy/util/langhelpers.py", line 72, in __exit__
    with_traceback=exc_tb,
  File "/home/airflow/.local/lib/python3.7/site-packages/sqlalchemy/util/compat.py", line 207, in raise_
    raise exception
  File "/home/airflow/.local/lib/python3.7/site-packages/sqlalchemy/pool/impl.py", line 143, in _do_get
    return self._create_connection()
  File "/home/airflow/.local/lib/python3.7/site-packages/sqlalchemy/pool/base.py", line 256, in _create_connection
    return _ConnectionRecord(self)
  File "/home/airflow/.local/lib/python3.7/site-packages/sqlalchemy/pool/base.py", line 371, in __init__
    self.__connect()
  File "/home/airflow/.local/lib/python3.7/site-packages/sqlalchemy/pool/base.py", line 666, in __connect
    pool.logger.debug("Error on connect(): %s", e)
  File "/home/airflow/.local/lib/python3.7/site-packages/sqlalchemy/util/langhelpers.py", line 72, in __exit__
    with_traceback=exc_tb,
  File "/home/airflow/.local/lib/python3.7/site-packages/sqlalchemy/util/compat.py", line 207, in raise_
    raise exception
  File "/home/airflow/.local/lib/python3.7/site-packages/sqlalchemy/pool/base.py", line 661, in __connect
    self.dbapi_connection = connection = pool._invoke_creator(self)
  File "/home/airflow/.local/lib/python3.7/site-packages/sqlalchemy/engine/create.py", line 590, in connect
    return dialect.connect(*cargs, **cparams)
  File "/home/airflow/.local/lib/python3.7/site-packages/sqlalchemy/engine/default.py", line 584, in connect
    return self.dbapi.connect(*cargs, **cparams)
  File "/home/airflow/.local/lib/python3.7/site-packages/psycopg2/__init__.py", line 122, in connect
    conn = _connect(dsn, connection_factory=connection_factory, **kwasync)
psycopg2.OperationalError: connection to server at "postgres" (172.21.0.3), port 5432 failed: Connection refused
	Is the server running on that host and accepting TCP/IP connections?


The above exception was the direct cause of the following exception:

Traceback (most recent call last):
  File "/home/airflow/.local/lib/python3.7/site-packages/airflow/dag_processing/processor.py", line 158, in _run_file_processor
    callback_requests=callback_requests,
  File "/home/airflow/.local/lib/python3.7/site-packages/airflow/utils/session.py", line 71, in wrapper
    return func(*args, session=session, **kwargs)
  File "/home/airflow/.local/lib/python3.7/site-packages/airflow/dag_processing/processor.py", line 660, in process_file
    dagbag.sync_to_db()
  File "/home/airflow/.local/lib/python3.7/site-packages/airflow/utils/session.py", line 71, in wrapper
    return func(*args, session=session, **kwargs)
  File "/home/airflow/.local/lib/python3.7/site-packages/airflow/models/dagbag.py", line 616, in sync_to_db
    for attempt in run_with_db_retries(logger=self.log):
  File "/home/airflow/.local/lib/python3.7/site-packages/tenacity/__init__.py", line 382, in __iter__
    do = self.iter(retry_state=retry_state)
  File "/home/airflow/.local/lib/python3.7/site-packages/tenacity/__init__.py", line 360, in iter
    raise retry_exc.reraise()
  File "/home/airflow/.local/lib/python3.7/site-packages/tenacity/__init__.py", line 193, in reraise
    raise self.last_attempt.result()
  File "/usr/local/lib/python3.7/concurrent/futures/_base.py", line 428, in result
    return self.__get_result()
  File "/usr/local/lib/python3.7/concurrent/futures/_base.py", line 384, in __get_result
    raise self._exception
  File "/home/airflow/.local/lib/python3.7/site-packages/airflow/models/dagbag.py", line 628, in sync_to_db
    serialize_errors.extend(_serialize_dag_capturing_errors(dag, session))
  File "/home/airflow/.local/lib/python3.7/site-packages/airflow/models/dagbag.py", line 602, in _serialize_dag_capturing_errors
    session=session,
  File "/home/airflow/.local/lib/python3.7/site-packages/airflow/utils/session.py", line 68, in wrapper
    return func(*args, **kwargs)
  File "/home/airflow/.local/lib/python3.7/site-packages/airflow/models/serialized_dag.py", line 142, in write_dag
    (timezone.utcnow() - timedelta(seconds=min_update_interval)) < cls.last_updated,
  File "/home/airflow/.local/lib/python3.7/site-packages/sqlalchemy/orm/query.py", line 2810, in first
    return self.limit(1)._iter().first()
  File "/home/airflow/.local/lib/python3.7/site-packages/sqlalchemy/orm/query.py", line 2897, in _iter
    execution_options={"_sa_orm_load_options": self.load_options},
  File "/home/airflow/.local/lib/python3.7/site-packages/sqlalchemy/orm/session.py", line 1688, in execute
    conn = self._connection_for_bind(bind)
  File "/home/airflow/.local/lib/python3.7/site-packages/sqlalchemy/orm/session.py", line 1530, in _connection_for_bind
    engine, execution_options
  File "/home/airflow/.local/lib/python3.7/site-packages/sqlalchemy/orm/session.py", line 747, in _connection_for_bind
    conn = bind.connect()
  File "/home/airflow/.local/lib/python3.7/site-packages/sqlalchemy/engine/base.py", line 3197, in connect
    return self._connection_cls(self, close_with_result=close_with_result)
  File "/home/airflow/.local/lib/python3.7/site-packages/sqlalchemy/engine/base.py", line 96, in __init__
    else engine.raw_connection()
  File "/home/airflow/.local/lib/python3.7/site-packages/sqlalchemy/engine/base.py", line 3276, in raw_connection
    return self._wrap_pool_connect(self.pool.connect, _connection)
  File "/home/airflow/.local/lib/python3.7/site-packages/sqlalchemy/engine/base.py", line 3247, in _wrap_pool_connect
    e, dialect, self
  File "/home/airflow/.local/lib/python3.7/site-packages/sqlalchemy/engine/base.py", line 2101, in _handle_dbapi_exception_noconnection
    sqlalchemy_exception, with_traceback=exc_info[2], from_=e
  File "/home/airflow/.local/lib/python3.7/site-packages/sqlalchemy/util/compat.py", line 207, in raise_
    raise exception
  File "/home/airflow/.local/lib/python3.7/site-packages/sqlalchemy/engine/base.py", line 3243, in _wrap_pool_connect
    return fn()
  File "/home/airflow/.local/lib/python3.7/site-packages/sqlalchemy/pool/base.py", line 310, in connect
    return _ConnectionFairy._checkout(self)
  File "/home/airflow/.local/lib/python3.7/site-packages/sqlalchemy/pool/base.py", line 868, in _checkout
    fairy = _ConnectionRecord.checkout(pool)
  File "/home/airflow/.local/lib/python3.7/site-packages/sqlalchemy/pool/base.py", line 476, in checkout
    rec = pool._do_get()
  File "/home/airflow/.local/lib/python3.7/site-packages/sqlalchemy/pool/impl.py", line 146, in _do_get
    self._dec_overflow()
  File "/home/airflow/.local/lib/python3.7/site-packages/sqlalchemy/util/langhelpers.py", line 72, in __exit__
    with_traceback=exc_tb,
  File "/home/airflow/.local/lib/python3.7/site-packages/sqlalchemy/util/compat.py", line 207, in raise_
    raise exception
  File "/home/airflow/.local/lib/python3.7/site-packages/sqlalchemy/pool/impl.py", line 143, in _do_get
    return self._create_connection()
  File "/home/airflow/.local/lib/python3.7/site-packages/sqlalchemy/pool/base.py", line 256, in _create_connection
    return _ConnectionRecord(self)
  File "/home/airflow/.local/lib/python3.7/site-packages/sqlalchemy/pool/base.py", line 371, in __init__
    self.__connect()
  File "/home/airflow/.local/lib/python3.7/site-packages/sqlalchemy/pool/base.py", line 666, in __connect
    pool.logger.debug("Error on connect(): %s", e)
  File "/home/airflow/.local/lib/python3.7/site-packages/sqlalchemy/util/langhelpers.py", line 72, in __exit__
    with_traceback=exc_tb,
  File "/home/airflow/.local/lib/python3.7/site-packages/sqlalchemy/util/compat.py", line 207, in raise_
    raise exception
  File "/home/airflow/.local/lib/python3.7/site-packages/sqlalchemy/pool/base.py", line 661, in __connect
    self.dbapi_connection = connection = pool._invoke_creator(self)
  File "/home/airflow/.local/lib/python3.7/site-packages/sqlalchemy/engine/create.py", line 590, in connect
    return dialect.connect(*cargs, **cparams)
  File "/home/airflow/.local/lib/python3.7/site-packages/sqlalchemy/engine/default.py", line 584, in connect
    return self.dbapi.connect(*cargs, **cparams)
  File "/home/airflow/.local/lib/python3.7/site-packages/psycopg2/__init__.py", line 122, in connect
    conn = _connect(dsn, connection_factory=connection_factory, **kwasync)
sqlalchemy.exc.OperationalError: (psycopg2.OperationalError) connection to server at "postgres" (172.21.0.3), port 5432 failed: Connection refused
	Is the server running on that host and accepting TCP/IP connections?

(Background on this error at: https://sqlalche.me/e/14/e3q8)
