[2022-08-21 15:04:52,370] {taskinstance.py:1179} INFO - Dependencies all met for <TaskInstance: extract_data_from_ftp_to_s3.ftp_to_s3_task scheduled__2022-08-21T14:00:00+00:00 [queued]>
[2022-08-21 15:04:52,384] {taskinstance.py:1179} INFO - Dependencies all met for <TaskInstance: extract_data_from_ftp_to_s3.ftp_to_s3_task scheduled__2022-08-21T14:00:00+00:00 [queued]>
[2022-08-21 15:04:52,385] {taskinstance.py:1376} INFO - 
--------------------------------------------------------------------------------
[2022-08-21 15:04:52,385] {taskinstance.py:1377} INFO - Starting attempt 1 of 1
[2022-08-21 15:04:52,385] {taskinstance.py:1378} INFO - 
--------------------------------------------------------------------------------
[2022-08-21 15:04:52,408] {taskinstance.py:1397} INFO - Executing <Task(FTPToS3Operator): ftp_to_s3_task> on 2022-08-21 14:00:00+00:00
[2022-08-21 15:04:52,414] {standard_task_runner.py:52} INFO - Started process 488 to run task
[2022-08-21 15:04:52,418] {standard_task_runner.py:79} INFO - Running: ['***', 'tasks', 'run', 'extract_data_from_ftp_to_s3', 'ftp_to_s3_task', 'scheduled__2022-08-21T14:00:00+00:00', '--job-id', '3', '--raw', '--subdir', 'DAGS_FOLDER/extract_data_from_ftp_to_s3.py', '--cfg-path', '/tmp/tmpnud5s4dp', '--error-file', '/tmp/tmpjdx05e6c']
[2022-08-21 15:04:52,418] {standard_task_runner.py:80} INFO - Job 3: Subtask ftp_to_s3_task
[2022-08-21 15:04:52,499] {task_command.py:371} INFO - Running <TaskInstance: extract_data_from_ftp_to_s3.ftp_to_s3_task scheduled__2022-08-21T14:00:00+00:00 [running]> on host 97b471418068
[2022-08-21 15:04:52,639] {taskinstance.py:1591} INFO - Exporting the following env vars:
AIRFLOW_CTX_DAG_OWNER=***
AIRFLOW_CTX_DAG_ID=extract_data_from_ftp_to_s3
AIRFLOW_CTX_TASK_ID=ftp_to_s3_task
AIRFLOW_CTX_EXECUTION_DATE=2022-08-21T14:00:00+00:00
AIRFLOW_CTX_TRY_NUMBER=1
AIRFLOW_CTX_DAG_RUN_ID=scheduled__2022-08-21T14:00:00+00:00
[2022-08-21 15:04:52,673] {taskinstance.py:1909} ERROR - Task failed with exception
Traceback (most recent call last):
  File "/home/airflow/.local/lib/python3.7/site-packages/airflow/providers/amazon/aws/transfers/ftp_to_s3.py", line 150, in execute
    self.__upload_to_s3_from_ftp(self.ftp_path, self.s3_key)
  File "/home/airflow/.local/lib/python3.7/site-packages/airflow/providers/amazon/aws/transfers/ftp_to_s3.py", line 99, in __upload_to_s3_from_ftp
    remote_full_path=remote_filename, local_full_path_or_buffer=local_tmp_file.name
  File "/home/airflow/.local/lib/python3.7/site-packages/airflow/providers/ftp/hooks/ftp.py", line 166, in retrieve_file
    conn = self.get_conn()
  File "/home/airflow/.local/lib/python3.7/site-packages/airflow/providers/ftp/hooks/ftp.py", line 60, in get_conn
    params = self.get_connection(self.ftp_conn_id)
  File "/home/airflow/.local/lib/python3.7/site-packages/airflow/hooks/base.py", line 67, in get_connection
    conn = Connection.get_connection_from_secrets(conn_id)
  File "/home/airflow/.local/lib/python3.7/site-packages/airflow/models/connection.py", line 430, in get_connection_from_secrets
    raise AirflowNotFoundException(f"The conn_id `{conn_id}` isn't defined")
airflow.exceptions.AirflowNotFoundException: The conn_id `ftp_default` isn't defined
[2022-08-21 15:04:52,678] {taskinstance.py:1420} INFO - Marking task as FAILED. dag_id=extract_data_from_ftp_to_s3, task_id=ftp_to_s3_task, execution_date=20220821T140000, start_date=20220821T150452, end_date=20220821T150452
[2022-08-21 15:04:52,695] {standard_task_runner.py:97} ERROR - Failed to execute job 3 for task ftp_to_s3_task (The conn_id `ftp_default` isn't defined; 488)
[2022-08-21 15:04:52,709] {local_task_job.py:156} INFO - Task exited with return code 1
[2022-08-21 15:04:52,759] {local_task_job.py:273} INFO - 0 downstream tasks scheduled from follow-on schedule check
