[2022-08-21 15:08:15,227] {taskinstance.py:1179} INFO - Dependencies all met for <TaskInstance: extract_data_from_ftp_to_s3.ftp_to_s3_task scheduled__2022-08-21T14:00:00+00:00 [queued]>
[2022-08-21 15:08:15,239] {taskinstance.py:1179} INFO - Dependencies all met for <TaskInstance: extract_data_from_ftp_to_s3.ftp_to_s3_task scheduled__2022-08-21T14:00:00+00:00 [queued]>
[2022-08-21 15:08:15,240] {taskinstance.py:1376} INFO - 
--------------------------------------------------------------------------------
[2022-08-21 15:08:15,240] {taskinstance.py:1377} INFO - Starting attempt 3 of 3
[2022-08-21 15:08:15,240] {taskinstance.py:1378} INFO - 
--------------------------------------------------------------------------------
[2022-08-21 15:08:15,258] {taskinstance.py:1397} INFO - Executing <Task(FTPToS3Operator): ftp_to_s3_task> on 2022-08-21 14:00:00+00:00
[2022-08-21 15:08:15,264] {standard_task_runner.py:52} INFO - Started process 645 to run task
[2022-08-21 15:08:15,267] {standard_task_runner.py:79} INFO - Running: ['***', 'tasks', 'run', 'extract_data_from_ftp_to_s3', 'ftp_to_s3_task', 'scheduled__2022-08-21T14:00:00+00:00', '--job-id', '5', '--raw', '--subdir', 'DAGS_FOLDER/extract_data_from_ftp_to_s3.py', '--cfg-path', '/tmp/tmpjhgq2w4v', '--error-file', '/tmp/tmpp5n7582e']
[2022-08-21 15:08:15,268] {standard_task_runner.py:80} INFO - Job 5: Subtask ftp_to_s3_task
[2022-08-21 15:08:15,354] {task_command.py:371} INFO - Running <TaskInstance: extract_data_from_ftp_to_s3.ftp_to_s3_task scheduled__2022-08-21T14:00:00+00:00 [running]> on host 97b471418068
[2022-08-21 15:08:15,448] {taskinstance.py:1591} INFO - Exporting the following env vars:
AIRFLOW_CTX_DAG_OWNER=***
AIRFLOW_CTX_DAG_ID=extract_data_from_ftp_to_s3
AIRFLOW_CTX_TASK_ID=ftp_to_s3_task
AIRFLOW_CTX_EXECUTION_DATE=2022-08-21T14:00:00+00:00
AIRFLOW_CTX_TRY_NUMBER=3
AIRFLOW_CTX_DAG_RUN_ID=scheduled__2022-08-21T14:00:00+00:00
[2022-08-21 15:08:15,462] {base.py:68} INFO - Using connection ID 'ftp_default' for task execution.
[2022-08-21 15:08:16,039] {taskinstance.py:1909} ERROR - Task failed with exception
Traceback (most recent call last):
  File "/home/airflow/.local/lib/python3.7/site-packages/airflow/providers/amazon/aws/transfers/ftp_to_s3.py", line 150, in execute
    self.__upload_to_s3_from_ftp(self.ftp_path, self.s3_key)
  File "/home/airflow/.local/lib/python3.7/site-packages/airflow/providers/amazon/aws/transfers/ftp_to_s3.py", line 99, in __upload_to_s3_from_ftp
    remote_full_path=remote_filename, local_full_path_or_buffer=local_tmp_file.name
  File "/home/airflow/.local/lib/python3.7/site-packages/airflow/providers/ftp/hooks/ftp.py", line 166, in retrieve_file
    conn = self.get_conn()
  File "/home/airflow/.local/lib/python3.7/site-packages/airflow/providers/ftp/hooks/ftp.py", line 62, in get_conn
    self.conn = ftplib.FTP(params.host, params.login, params.password)
  File "/usr/local/lib/python3.7/ftplib.py", line 121, in __init__
    self.login(user, passwd, acct)
  File "/usr/local/lib/python3.7/ftplib.py", line 427, in login
    resp = self.sendcmd('PASS ' + passwd)
  File "/usr/local/lib/python3.7/ftplib.py", line 275, in sendcmd
    return self.getresp()
  File "/usr/local/lib/python3.7/ftplib.py", line 248, in getresp
    raise error_perm(resp)
ftplib.error_perm: 530 User cannot log in.
[2022-08-21 15:08:16,051] {taskinstance.py:1420} INFO - Marking task as FAILED. dag_id=extract_data_from_ftp_to_s3, task_id=ftp_to_s3_task, execution_date=20220821T140000, start_date=20220821T150815, end_date=20220821T150816
[2022-08-21 15:08:16,077] {standard_task_runner.py:97} ERROR - Failed to execute job 5 for task ftp_to_s3_task (530 User cannot log in.; 645)
[2022-08-21 15:08:16,121] {local_task_job.py:156} INFO - Task exited with return code 1
[2022-08-21 15:08:16,192] {local_task_job.py:273} INFO - 0 downstream tasks scheduled from follow-on schedule check
