[2022-08-21 15:06:08,464] {taskinstance.py:1179} INFO - Dependencies all met for <TaskInstance: extract_data_from_ftp_to_s3.ftp_to_s3_task scheduled__2022-08-21T14:00:00+00:00 [queued]>
[2022-08-21 15:06:08,482] {taskinstance.py:1179} INFO - Dependencies all met for <TaskInstance: extract_data_from_ftp_to_s3.ftp_to_s3_task scheduled__2022-08-21T14:00:00+00:00 [queued]>
[2022-08-21 15:06:08,483] {taskinstance.py:1376} INFO - 
--------------------------------------------------------------------------------
[2022-08-21 15:06:08,483] {taskinstance.py:1377} INFO - Starting attempt 2 of 2
[2022-08-21 15:06:08,483] {taskinstance.py:1378} INFO - 
--------------------------------------------------------------------------------
[2022-08-21 15:06:08,512] {taskinstance.py:1397} INFO - Executing <Task(FTPToS3Operator): ftp_to_s3_task> on 2022-08-21 14:00:00+00:00
[2022-08-21 15:06:08,520] {standard_task_runner.py:52} INFO - Started process 552 to run task
[2022-08-21 15:06:08,523] {standard_task_runner.py:79} INFO - Running: ['***', 'tasks', 'run', 'extract_data_from_ftp_to_s3', 'ftp_to_s3_task', 'scheduled__2022-08-21T14:00:00+00:00', '--job-id', '4', '--raw', '--subdir', 'DAGS_FOLDER/extract_data_from_ftp_to_s3.py', '--cfg-path', '/tmp/tmp93dgevx5', '--error-file', '/tmp/tmpu9j6jfc5']
[2022-08-21 15:06:08,523] {standard_task_runner.py:80} INFO - Job 4: Subtask ftp_to_s3_task
[2022-08-21 15:06:08,620] {task_command.py:371} INFO - Running <TaskInstance: extract_data_from_ftp_to_s3.ftp_to_s3_task scheduled__2022-08-21T14:00:00+00:00 [running]> on host 97b471418068
[2022-08-21 15:06:08,739] {taskinstance.py:1591} INFO - Exporting the following env vars:
AIRFLOW_CTX_DAG_OWNER=***
AIRFLOW_CTX_DAG_ID=extract_data_from_ftp_to_s3
AIRFLOW_CTX_TASK_ID=ftp_to_s3_task
AIRFLOW_CTX_EXECUTION_DATE=2022-08-21T14:00:00+00:00
AIRFLOW_CTX_TRY_NUMBER=2
AIRFLOW_CTX_DAG_RUN_ID=scheduled__2022-08-21T14:00:00+00:00
[2022-08-21 15:06:08,753] {base.py:68} INFO - Using connection ID 'ftp_default' for task execution.
[2022-08-21 15:06:09,244] {taskinstance.py:1909} ERROR - Task failed with exception
Traceback (most recent call last):
  File "/home/airflow/.local/lib/python3.7/site-packages/airflow/providers/amazon/aws/transfers/ftp_to_s3.py", line 150, in execute
    self.__upload_to_s3_from_ftp(self.ftp_path, self.s3_key)
  File "/home/airflow/.local/lib/python3.7/site-packages/airflow/providers/amazon/aws/transfers/ftp_to_s3.py", line 99, in __upload_to_s3_from_ftp
    remote_full_path=remote_filename, local_full_path_or_buffer=local_tmp_file.name
  File "/home/airflow/.local/lib/python3.7/site-packages/airflow/providers/ftp/hooks/ftp.py", line 183, in retrieve_file
    conn.cwd(remote_path)
  File "/usr/local/lib/python3.7/ftplib.py", line 638, in cwd
    return self.voidcmd(cmd)
  File "/usr/local/lib/python3.7/ftplib.py", line 280, in voidcmd
    return self.voidresp()
  File "/usr/local/lib/python3.7/ftplib.py", line 253, in voidresp
    resp = self.getresp()
  File "/usr/local/lib/python3.7/ftplib.py", line 248, in getresp
    raise error_perm(resp)
ftplib.error_perm: 530 Please login with USER and PASS.
[2022-08-21 15:06:09,260] {taskinstance.py:1420} INFO - Marking task as FAILED. dag_id=extract_data_from_ftp_to_s3, task_id=ftp_to_s3_task, execution_date=20220821T140000, start_date=20220821T150608, end_date=20220821T150609
[2022-08-21 15:06:09,284] {standard_task_runner.py:97} ERROR - Failed to execute job 4 for task ftp_to_s3_task (530 Please login with USER and PASS.; 552)
[2022-08-21 15:06:09,297] {local_task_job.py:156} INFO - Task exited with return code 1
[2022-08-21 15:06:09,371] {local_task_job.py:273} INFO - 0 downstream tasks scheduled from follow-on schedule check
