[2022-10-15 23:31:14,888] {taskinstance.py:1179} INFO - Dependencies all met for <TaskInstance: test_dag.upload_to_s3 scheduled__2022-10-14T00:00:00+00:00 [queued]>
[2022-10-15 23:31:14,905] {taskinstance.py:1179} INFO - Dependencies all met for <TaskInstance: test_dag.upload_to_s3 scheduled__2022-10-14T00:00:00+00:00 [queued]>
[2022-10-15 23:31:14,905] {taskinstance.py:1376} INFO - 
--------------------------------------------------------------------------------
[2022-10-15 23:31:14,905] {taskinstance.py:1377} INFO - Starting attempt 18 of 18
[2022-10-15 23:31:14,905] {taskinstance.py:1378} INFO - 
--------------------------------------------------------------------------------
[2022-10-15 23:31:14,927] {taskinstance.py:1397} INFO - Executing <Task(PythonOperator): upload_to_s3> on 2022-10-14 00:00:00+00:00
[2022-10-15 23:31:14,933] {standard_task_runner.py:52} INFO - Started process 16895 to run task
[2022-10-15 23:31:14,937] {standard_task_runner.py:79} INFO - Running: ['***', 'tasks', 'run', 'test_dag', 'upload_to_s3', 'scheduled__2022-10-14T00:00:00+00:00', '--job-id', '96', '--raw', '--subdir', 'DAGS_FOLDER/test_dag.py', '--cfg-path', '/tmp/tmpugh1_cdd', '--error-file', '/tmp/tmp_7hiigh5']
[2022-10-15 23:31:14,937] {standard_task_runner.py:80} INFO - Job 96: Subtask upload_to_s3
[2022-10-15 23:31:15,017] {task_command.py:371} INFO - Running <TaskInstance: test_dag.upload_to_s3 scheduled__2022-10-14T00:00:00+00:00 [running]> on host e1202d78ead4
[2022-10-15 23:31:15,114] {taskinstance.py:1591} INFO - Exporting the following env vars:
AIRFLOW_CTX_DAG_OWNER=***
AIRFLOW_CTX_DAG_ID=test_dag
AIRFLOW_CTX_TASK_ID=upload_to_s3
AIRFLOW_CTX_EXECUTION_DATE=2022-10-14T00:00:00+00:00
AIRFLOW_CTX_TRY_NUMBER=18
AIRFLOW_CTX_DAG_RUN_ID=scheduled__2022-10-14T00:00:00+00:00
[2022-10-15 23:31:15,128] {base.py:68} INFO - Using connection ID 'local_minio' for task execution.
[2022-10-15 23:31:15,129] {base_aws.py:210} INFO - Credentials retrieved from extra_config
[2022-10-15 23:31:15,200] {taskinstance.py:1909} ERROR - Task failed with exception
Traceback (most recent call last):
  File "/home/airflow/.local/lib/python3.7/site-packages/airflow/operators/python.py", line 171, in execute
    return_value = self.execute_callable()
  File "/home/airflow/.local/lib/python3.7/site-packages/airflow/operators/python.py", line 189, in execute_callable
    return self.python_callable(*self.op_args, **self.op_kwargs)
  File "/opt/airflow/dags/test_dag.py", line 9, in upload_to_s3
    hook.load_file(filename=filename, key=key, bucket_name=bucket_name)
  File "/home/airflow/.local/lib/python3.7/site-packages/airflow/providers/amazon/aws/hooks/s3.py", line 63, in wrapper
    return func(*bound_args.args, **bound_args.kwargs)
  File "/home/airflow/.local/lib/python3.7/site-packages/airflow/providers/amazon/aws/hooks/s3.py", line 91, in wrapper
    return func(*bound_args.args, **bound_args.kwargs)
  File "/home/airflow/.local/lib/python3.7/site-packages/airflow/providers/amazon/aws/hooks/s3.py", line 611, in load_file
    client.upload_file(filename, bucket_name, key, ExtraArgs=extra_args, Config=self.transfer_config)
  File "/home/airflow/.local/lib/python3.7/site-packages/boto3/s3/inject.py", line 148, in upload_file
    callback=Callback,
  File "/home/airflow/.local/lib/python3.7/site-packages/boto3/s3/transfer.py", line 288, in upload_file
    future.result()
  File "/home/airflow/.local/lib/python3.7/site-packages/s3transfer/futures.py", line 103, in result
    return self._coordinator.result()
  File "/home/airflow/.local/lib/python3.7/site-packages/s3transfer/futures.py", line 266, in result
    raise self._exception
  File "/home/airflow/.local/lib/python3.7/site-packages/s3transfer/tasks.py", line 269, in _main
    self._submit(transfer_future=transfer_future, **kwargs)
  File "/home/airflow/.local/lib/python3.7/site-packages/s3transfer/upload.py", line 585, in _submit
    upload_input_manager.provide_transfer_size(transfer_future)
  File "/home/airflow/.local/lib/python3.7/site-packages/s3transfer/upload.py", line 244, in provide_transfer_size
    self._osutil.get_file_size(transfer_future.meta.call_args.fileobj)
  File "/home/airflow/.local/lib/python3.7/site-packages/s3transfer/utils.py", line 247, in get_file_size
    return os.path.getsize(filename)
  File "/usr/local/lib/python3.7/genericpath.py", line 50, in getsize
    return os.stat(filename).st_size
FileNotFoundError: [Errno 2] No such file or directory: '/opt/airflow/test.txt'
[2022-10-15 23:31:15,213] {taskinstance.py:1420} INFO - Marking task as FAILED. dag_id=test_dag, task_id=upload_to_s3, execution_date=20221014T000000, start_date=20221015T233114, end_date=20221015T233115
[2022-10-15 23:31:15,227] {standard_task_runner.py:97} ERROR - Failed to execute job 96 for task upload_to_s3 ([Errno 2] No such file or directory: '/opt/airflow/test.txt'; 16895)
[2022-10-15 23:31:15,268] {local_task_job.py:156} INFO - Task exited with return code 1
[2022-10-15 23:31:15,310] {local_task_job.py:273} INFO - 0 downstream tasks scheduled from follow-on schedule check
