[2022-10-15 22:52:43,107] {taskinstance.py:1179} INFO - Dependencies all met for <TaskInstance: test_dag.upload_to_s3 scheduled__2022-10-14T00:00:00+00:00 [queued]>
[2022-10-15 22:52:43,122] {taskinstance.py:1179} INFO - Dependencies all met for <TaskInstance: test_dag.upload_to_s3 scheduled__2022-10-14T00:00:00+00:00 [queued]>
[2022-10-15 22:52:43,122] {taskinstance.py:1376} INFO - 
--------------------------------------------------------------------------------
[2022-10-15 22:52:43,122] {taskinstance.py:1377} INFO - Starting attempt 3 of 3
[2022-10-15 22:52:43,123] {taskinstance.py:1378} INFO - 
--------------------------------------------------------------------------------
[2022-10-15 22:52:43,147] {taskinstance.py:1397} INFO - Executing <Task(PythonOperator): upload_to_s3> on 2022-10-14 00:00:00+00:00
[2022-10-15 22:52:43,153] {standard_task_runner.py:52} INFO - Started process 15112 to run task
[2022-10-15 22:52:43,157] {standard_task_runner.py:79} INFO - Running: ['***', 'tasks', 'run', 'test_dag', 'upload_to_s3', 'scheduled__2022-10-14T00:00:00+00:00', '--job-id', '81', '--raw', '--subdir', 'DAGS_FOLDER/test_dag.py', '--cfg-path', '/tmp/tmp8y8ybzh8', '--error-file', '/tmp/tmpwlot68_f']
[2022-10-15 22:52:43,157] {standard_task_runner.py:80} INFO - Job 81: Subtask upload_to_s3
[2022-10-15 22:52:43,245] {task_command.py:371} INFO - Running <TaskInstance: test_dag.upload_to_s3 scheduled__2022-10-14T00:00:00+00:00 [running]> on host e1202d78ead4
[2022-10-15 22:52:43,381] {taskinstance.py:1591} INFO - Exporting the following env vars:
AIRFLOW_CTX_DAG_OWNER=***
AIRFLOW_CTX_DAG_ID=test_dag
AIRFLOW_CTX_TASK_ID=upload_to_s3
AIRFLOW_CTX_EXECUTION_DATE=2022-10-14T00:00:00+00:00
AIRFLOW_CTX_TRY_NUMBER=3
AIRFLOW_CTX_DAG_RUN_ID=scheduled__2022-10-14T00:00:00+00:00
[2022-10-15 22:52:43,396] {base.py:68} INFO - Using connection ID 's3_conn' for task execution.
[2022-10-15 22:52:43,398] {base_aws.py:206} INFO - Credentials retrieved from login
[2022-10-15 22:52:43,485] {taskinstance.py:1909} ERROR - Task failed with exception
Traceback (most recent call last):
  File "/home/airflow/.local/lib/python3.7/site-packages/airflow/operators/python.py", line 171, in execute
    return_value = self.execute_callable()
  File "/home/airflow/.local/lib/python3.7/site-packages/airflow/operators/python.py", line 189, in execute_callable
    return self.python_callable(*self.op_args, **self.op_kwargs)
  File "/opt/airflow/dags/test_dag.py", line 9, in upload_to_s3
    hook.load_file(filename=filename, key=key, bucket_name=bucket_name)
  File "/home/airflow/.local/lib/python3.7/site-packages/airflow/providers/amazon/aws/hooks/s3.py", line 63, in wrapper
    return func(*bound_args.args, **bound_args.kwargs)
  File "/home/airflow/.local/lib/python3.7/site-packages/airflow/providers/amazon/aws/hooks/s3.py", line 91, in wrapper
    return func(*bound_args.args, **bound_args.kwargs)
  File "/home/airflow/.local/lib/python3.7/site-packages/airflow/providers/amazon/aws/hooks/s3.py", line 595, in load_file
    if not replace and self.check_for_key(key, bucket_name):
  File "/home/airflow/.local/lib/python3.7/site-packages/airflow/providers/amazon/aws/hooks/s3.py", line 63, in wrapper
    return func(*bound_args.args, **bound_args.kwargs)
  File "/home/airflow/.local/lib/python3.7/site-packages/airflow/providers/amazon/aws/hooks/s3.py", line 91, in wrapper
    return func(*bound_args.args, **bound_args.kwargs)
  File "/home/airflow/.local/lib/python3.7/site-packages/airflow/providers/amazon/aws/hooks/s3.py", line 438, in check_for_key
    obj = self.head_object(key, bucket_name)
  File "/home/airflow/.local/lib/python3.7/site-packages/airflow/providers/amazon/aws/hooks/s3.py", line 63, in wrapper
    return func(*bound_args.args, **bound_args.kwargs)
  File "/home/airflow/.local/lib/python3.7/site-packages/airflow/providers/amazon/aws/hooks/s3.py", line 91, in wrapper
    return func(*bound_args.args, **bound_args.kwargs)
  File "/home/airflow/.local/lib/python3.7/site-packages/airflow/providers/amazon/aws/hooks/s3.py", line 420, in head_object
    return self.get_conn().head_object(Bucket=bucket_name, Key=key)
  File "/home/airflow/.local/lib/python3.7/site-packages/airflow/providers/amazon/aws/hooks/base_aws.py", line 535, in get_conn
    return self.conn
  File "/home/airflow/.local/lib/python3.7/site-packages/cached_property.py", line 36, in __get__
    value = obj.__dict__[self.func.__name__] = self.func(obj)
  File "/home/airflow/.local/lib/python3.7/site-packages/airflow/providers/amazon/aws/hooks/base_aws.py", line 517, in conn
    return self.get_client_type(region_name=self.region_name)
  File "/home/airflow/.local/lib/python3.7/site-packages/airflow/providers/amazon/aws/hooks/base_aws.py", line 481, in get_client_type
    return session.client(client_type, endpoint_url=endpoint_url, config=config, verify=self.verify)
  File "/home/airflow/.local/lib/python3.7/site-packages/boto3/session.py", line 309, in client
    config=config,
  File "/home/airflow/.local/lib/python3.7/site-packages/botocore/session.py", line 959, in create_client
    api_version=api_version,
  File "/home/airflow/.local/lib/python3.7/site-packages/botocore/client.py", line 132, in create_client
    endpoint_bridge,
  File "/home/airflow/.local/lib/python3.7/site-packages/botocore/client.py", line 475, in _get_client_args
    endpoint_bridge,
  File "/home/airflow/.local/lib/python3.7/site-packages/botocore/args.py", line 134, in get_client_args
    proxies_config=new_config.proxies_config,
  File "/home/airflow/.local/lib/python3.7/site-packages/botocore/endpoint.py", line 402, in create_endpoint
    raise ValueError("Invalid endpoint: %s" % endpoint_url)
ValueError: Invalid endpoint: host.docker.internal:9000
[2022-10-15 22:52:43,511] {taskinstance.py:1420} INFO - Marking task as FAILED. dag_id=test_dag, task_id=upload_to_s3, execution_date=20221014T000000, start_date=20221015T225243, end_date=20221015T225243
[2022-10-15 22:52:43,532] {standard_task_runner.py:97} ERROR - Failed to execute job 81 for task upload_to_s3 (Invalid endpoint: host.docker.internal:9000; 15112)
[2022-10-15 22:52:43,570] {local_task_job.py:156} INFO - Task exited with return code 1
[2022-10-15 22:52:43,614] {local_task_job.py:273} INFO - 0 downstream tasks scheduled from follow-on schedule check
