[2022-10-15 23:07:11,261] {taskinstance.py:1179} INFO - Dependencies all met for <TaskInstance: test_dag.upload_to_s3 scheduled__2022-10-14T00:00:00+00:00 [queued]>
[2022-10-15 23:07:11,272] {taskinstance.py:1179} INFO - Dependencies all met for <TaskInstance: test_dag.upload_to_s3 scheduled__2022-10-14T00:00:00+00:00 [queued]>
[2022-10-15 23:07:11,273] {taskinstance.py:1376} INFO - 
--------------------------------------------------------------------------------
[2022-10-15 23:07:11,273] {taskinstance.py:1377} INFO - Starting attempt 10 of 10
[2022-10-15 23:07:11,273] {taskinstance.py:1378} INFO - 
--------------------------------------------------------------------------------
[2022-10-15 23:07:11,290] {taskinstance.py:1397} INFO - Executing <Task(PythonOperator): upload_to_s3> on 2022-10-14 00:00:00+00:00
[2022-10-15 23:07:11,296] {standard_task_runner.py:52} INFO - Started process 15777 to run task
[2022-10-15 23:07:11,300] {standard_task_runner.py:79} INFO - Running: ['***', 'tasks', 'run', 'test_dag', 'upload_to_s3', 'scheduled__2022-10-14T00:00:00+00:00', '--job-id', '88', '--raw', '--subdir', 'DAGS_FOLDER/test_dag.py', '--cfg-path', '/tmp/tmp6n1g8rgt', '--error-file', '/tmp/tmpoas1ltad']
[2022-10-15 23:07:11,301] {standard_task_runner.py:80} INFO - Job 88: Subtask upload_to_s3
[2022-10-15 23:07:11,377] {task_command.py:371} INFO - Running <TaskInstance: test_dag.upload_to_s3 scheduled__2022-10-14T00:00:00+00:00 [running]> on host e1202d78ead4
[2022-10-15 23:07:11,470] {taskinstance.py:1591} INFO - Exporting the following env vars:
AIRFLOW_CTX_DAG_OWNER=***
AIRFLOW_CTX_DAG_ID=test_dag
AIRFLOW_CTX_TASK_ID=upload_to_s3
AIRFLOW_CTX_EXECUTION_DATE=2022-10-14T00:00:00+00:00
AIRFLOW_CTX_TRY_NUMBER=10
AIRFLOW_CTX_DAG_RUN_ID=scheduled__2022-10-14T00:00:00+00:00
[2022-10-15 23:07:11,483] {base.py:68} INFO - Using connection ID 'local_minio' for task execution.
[2022-10-15 23:07:11,484] {base_aws.py:206} INFO - Credentials retrieved from login
[2022-10-15 23:07:12,466] {taskinstance.py:1909} ERROR - Task failed with exception
Traceback (most recent call last):
  File "/home/airflow/.local/lib/python3.7/site-packages/airflow/operators/python.py", line 171, in execute
    return_value = self.execute_callable()
  File "/home/airflow/.local/lib/python3.7/site-packages/airflow/operators/python.py", line 189, in execute_callable
    return self.python_callable(*self.op_args, **self.op_kwargs)
  File "/opt/airflow/dags/test_dag.py", line 9, in upload_to_s3
    hook.load_file(filename=filename, key=key, bucket_name=bucket_name)
  File "/home/airflow/.local/lib/python3.7/site-packages/airflow/providers/amazon/aws/hooks/s3.py", line 63, in wrapper
    return func(*bound_args.args, **bound_args.kwargs)
  File "/home/airflow/.local/lib/python3.7/site-packages/airflow/providers/amazon/aws/hooks/s3.py", line 91, in wrapper
    return func(*bound_args.args, **bound_args.kwargs)
  File "/home/airflow/.local/lib/python3.7/site-packages/airflow/providers/amazon/aws/hooks/s3.py", line 595, in load_file
    if not replace and self.check_for_key(key, bucket_name):
  File "/home/airflow/.local/lib/python3.7/site-packages/airflow/providers/amazon/aws/hooks/s3.py", line 63, in wrapper
    return func(*bound_args.args, **bound_args.kwargs)
  File "/home/airflow/.local/lib/python3.7/site-packages/airflow/providers/amazon/aws/hooks/s3.py", line 91, in wrapper
    return func(*bound_args.args, **bound_args.kwargs)
  File "/home/airflow/.local/lib/python3.7/site-packages/airflow/providers/amazon/aws/hooks/s3.py", line 438, in check_for_key
    obj = self.head_object(key, bucket_name)
  File "/home/airflow/.local/lib/python3.7/site-packages/airflow/providers/amazon/aws/hooks/s3.py", line 63, in wrapper
    return func(*bound_args.args, **bound_args.kwargs)
  File "/home/airflow/.local/lib/python3.7/site-packages/airflow/providers/amazon/aws/hooks/s3.py", line 91, in wrapper
    return func(*bound_args.args, **bound_args.kwargs)
  File "/home/airflow/.local/lib/python3.7/site-packages/airflow/providers/amazon/aws/hooks/s3.py", line 425, in head_object
    raise e
  File "/home/airflow/.local/lib/python3.7/site-packages/airflow/providers/amazon/aws/hooks/s3.py", line 420, in head_object
    return self.get_conn().head_object(Bucket=bucket_name, Key=key)
  File "/home/airflow/.local/lib/python3.7/site-packages/botocore/client.py", line 508, in _api_call
    return self._make_api_call(operation_name, kwargs)
  File "/home/airflow/.local/lib/python3.7/site-packages/botocore/client.py", line 915, in _make_api_call
    raise error_class(parsed_response, operation_name)
botocore.exceptions.ClientError: An error occurred (403) when calling the HeadObject operation: Forbidden
[2022-10-15 23:07:12,479] {taskinstance.py:1420} INFO - Marking task as FAILED. dag_id=test_dag, task_id=upload_to_s3, execution_date=20221014T000000, start_date=20221015T230711, end_date=20221015T230712
[2022-10-15 23:07:12,500] {standard_task_runner.py:97} ERROR - Failed to execute job 88 for task upload_to_s3 (An error occurred (403) when calling the HeadObject operation: Forbidden; 15777)
[2022-10-15 23:07:12,553] {local_task_job.py:156} INFO - Task exited with return code 1
[2022-10-15 23:07:12,603] {local_task_job.py:273} INFO - 0 downstream tasks scheduled from follow-on schedule check
